<?xml version="1.0" ?>
<sdf version="1.8">
  <model name='simple_robot'>
    <pose>0 0 0.3 0 0 0</pose>
    
    <!-- Chassis -->
    <link name='chassis'>
      <pose>0 0 0.15 0 0 0</pose>
      <inertial>
        <mass>5.0</mass>
        <inertia>
          <ixx>0.5</ixx> <iyy>0.5</iyy> <izz>0.5</izz>
        </inertia>
      </inertial>
      <visual name='visual'>
        <geometry>
          <box><size>0.6 0.4 0.2</size></box>
        </geometry>
        <material>
          <ambient>0 0 1 1</ambient>
          <diffuse>0 0 1 1</diffuse>
        </material>
      </visual>
      <collision name='collision'>
        <geometry>
          <box><size>0.6 0.4 0.2</size></box>
        </geometry>
      </collision>
    </link>
    
    <!-- Left Wheel -->
    <link name='left_wheel'>
      <pose>0 0.25 0.15 -1.5707 0 0</pose>
      <inertial>
        <mass>1</mass>
        <inertia>
          <ixx>0.05</ixx> <iyy>0.05</iyy> <izz>0.05</izz>
        </inertia>
      </inertial>
      <visual name='visual'>
        <geometry>
          <cylinder>
            <radius>0.15</radius>
            <length>0.1</length>
          </cylinder>
        </geometry>
        <material>
          <ambient>0.2 0.2 0.2 1</ambient>
        </material>
      </visual>
      <collision name='collision'>
        <geometry>
          <cylinder>
            <radius>0.15</radius>
            <length>0.1</length>
          </cylinder>
        </geometry>
        <surface>
          <friction>
            <ode><mu>1.0</mu><mu2>1.0</mu2></ode>
          </friction>
        </surface>
      </collision>
    </link>
    
    <!-- Right Wheel -->
    <link name='right_wheel'>
      <pose>0 -0.25 0.15 -1.5707 0 0</pose>
      <inertial>
        <mass>1</mass>
        <inertia>
          <ixx>0.05</ixx> <iyy>0.05</iyy> <izz>0.05</izz>
        </inertia>
      </inertial>
      <visual name='visual'>
        <geometry>
          <cylinder>
            <radius>0.15</radius>
            <length>0.1</length>
          </cylinder>
        </geometry>
        <material>
          <ambient>0.2 0.2 0.2 1</ambient>
        </material>
      </visual>
      <collision name='collision'>
        <geometry>
          <cylinder>
            <radius>0.15</radius>
            <length>0.1</length>
          </cylinder>
        </geometry>
        <surface>
          <friction>
            <ode><mu>1.0</mu><mu2>1.0</mu2></ode>
          </friction>
        </surface>
      </collision>
    </link>
    
    <!-- Joints -->
    <joint name='left_wheel_joint' type='revolute'>
      <parent>chassis</parent>
      <child>left_wheel</child>
      <axis>
        <xyz>0 0 1</xyz>
        <limit>
          <effort>10</effort>
          <velocity>100</velocity>
        </limit>
        <dynamics>
          <damping>0.5</damping>
          <friction>0.1</friction>
        </dynamics>
      </axis>
    </joint>
    
    <joint name='right_wheel_joint' type='revolute'>
      <parent>chassis</parent>
      <child>right_wheel</child>
      <axis>
        <xyz>0 0 1</xyz>
        <limit>
          <effort>10</effort>
          <velocity>100</velocity>
        </limit>
        <dynamics>
          <damping>0.5</damping>
          <friction>0.1</friction>
        </dynamics>
      </axis>
    </joint>
    
    <!-- Odometry Publisher -->
    <plugin filename="gz-sim-odometry-publisher-system"
            name="gz::sim::systems::OdometryPublisher">
      <odom_frame>odom</odom_frame>
      <robot_base_frame>chassis</robot_base_frame>
      <odom_topic>/odom</odom_topic>
      <odom_publish_frequency>20</odom_publish_frequency>
    </plugin>
    
    <!-- Joint Force Plugins (like the working wheel test) -->
    <plugin filename="gz-sim-apply-joint-force-system" 
            name="gz::sim::systems::ApplyJointForce">
      <joint_name>left_wheel_joint</joint_name>
    </plugin>
    
    <plugin filename="gz-sim-apply-joint-force-system" 
            name="gz::sim::systems::ApplyJointForce">
      <joint_name>right_wheel_joint</joint_name>
    </plugin>
    
  </model>
</sdf>
