<?xml version="1.0"?>
<sdf version="1.9">
  <model name="rl_training_car">

    <!-- Base Link (chassis) -->
    <link name="base_link">
      <pose>0 0 0.3 0 0 0</pose>

      <inertial>
        <mass>10.0</mass>
        <inertia>
          <ixx>2.0</ixx>
          <iyy>2.0</iyy>
          <izz>2.0</izz>
        </inertia>
      </inertial>

      <collision name="collision">
        <geometry>
          <box>
            <size>2.0 1.0 0.5</size>
          </box>
        </geometry>
      </collision>

      <visual name="visual">
        <geometry>
          <box>
            <size>2.0 1.0 0.5</size>
          </box>
        </geometry>
        <material>
          <ambient>0.2 0.8 0.2 1.0</ambient>
          <diffuse>0.2 0.8 0.2 1.0</diffuse>
        </material>
      </visual>
    </link>

<!-- ... (skipping sensor/wheel links for brevity of edit tool, but only changing base_link here is safer if I use correct target) -->
<!-- Wait, replace_file_content requires me to match the block. I will target the Base Link block specifically. -->

    <!-- 2D LiDAR Sensor -->
    <link name="lidar_link">
      <pose relative_to="base_link">0 0 0.4 0 0 0</pose>

      <inertial>
        <mass>0.1</mass>
        <inertia>
          <ixx>0.001</ixx>
          <iyy>0.001</iyy>
          <izz>0.001</izz>
        </inertia>
      </inertial>

      <visual name="visual">
        <geometry>
          <cylinder>
            <radius>0.05</radius>
            <length>0.07</length>
          </cylinder>
        </geometry>
        <material>
          <ambient>0.0 0.0 0.0 1.0</ambient>
          <diffuse>0.0 0.0 0.0 1.0</diffuse>
        </material>
      </visual>

      <sensor name="lidar" type="gpu_lidar">
        <pose>0 0 0 0 0 0</pose>
        <topic>/scan</topic>
        <update_rate>10</update_rate>
        <lidar>
          <scan>
            <horizontal>
              <samples>360</samples>
              <resolution>1</resolution>
              <min_angle>-3.14159</min_angle>
              <max_angle>3.14159</max_angle>
            </horizontal>
          </scan>
          <range>
            <min>0.1</min>
            <max>10.0</max>
            <resolution>0.01</resolution>
          </range>
          <noise>
            <type>gaussian</type>
            <mean>0.0</mean>
            <stddev>0.01</stddev>
          </noise>
        </lidar>
        <always_on>1</always_on>
        <visualize>true</visualize>
      </sensor>
    </link>

    <joint name="lidar_joint" type="fixed">
      <parent>base_link</parent>
      <child>lidar_link</child>
    </joint>

    <!-- Front Camera (optional for future vision-based RL) -->
    <link name="camera_link">
      <pose relative_to="base_link">1.0 0 0.35 0 0 0</pose>

      <inertial>
        <mass>0.1</mass>
        <inertia>
          <ixx>0.001</ixx>
          <iyy>0.001</iyy>
          <izz>0.001</izz>
        </inertia>
      </inertial>

      <visual name="visual">
        <geometry>
          <box>
            <size>0.05 0.05 0.05</size>
          </box>
        </geometry>
        <material>
          <ambient>1.0 0.0 0.0 1.0</ambient>
          <diffuse>1.0 0.0 0.0 1.0</diffuse>
        </material>
      </visual>

      <sensor name="camera" type="camera">
        <camera>
          <horizontal_fov>1.047</horizontal_fov>
          <image>
            <width>320</width>
            <height>240</height>
          </image>
          <clip>
            <near>0.1</near>
            <far>100</far>
          </clip>
        </camera>
        <always_on>1</always_on>
        <update_rate>10</update_rate>
        <visualize>false</visualize>
        <topic>/camera/image_raw</topic>
      </sensor>
    </link>

    <joint name="camera_joint" type="fixed">
      <parent>base_link</parent>
      <child>camera_link</child>
    </joint>

    <!-- Wheels -->
    <link name="front_left_wheel">
      <pose relative_to="base_link">0.7 0.75 0 -1.5708 0 0</pose>
      <inertial>
        <mass>5.0</mass>
        <inertia>
          <ixx>0.1</ixx>
          <iyy>0.1</iyy>
          <izz>0.1</izz>
        </inertia>
      </inertial>
      <collision name="collision">
        <geometry>
          <cylinder>
            <radius>0.3</radius>
            <length>0.2</length>
          </cylinder>
        </geometry>
      </collision>
      <visual name="visual">
        <geometry>
          <cylinder>
            <radius>0.3</radius>
            <length>0.2</length>
          </cylinder>
        </geometry>
        <material>
          <ambient>0.1 0.1 0.1 1.0</ambient>
          <diffuse>0.1 0.1 0.1 1.0</diffuse>
        </material>
      </visual>
    </link>

    <joint name="front_left_wheel_joint" type="revolute">
      <parent>base_link</parent>
      <child>front_left_wheel</child>
      <axis>
        <xyz>0 1 0</xyz>
        <limit>
            <lower>-1.79769e+308</lower>
            <upper>1.79769e+308</upper>
        </limit>
      </axis>
    </joint>

    <link name="front_right_wheel">
      <pose relative_to="base_link">0.7 -0.75 0 -1.5708 0 0</pose>
      <inertial>
        <mass>5.0</mass>
        <inertia>
          <ixx>0.1</ixx>
          <iyy>0.1</iyy>
          <izz>0.1</izz>
        </inertia>
      </inertial>
      <collision name="collision">
        <geometry>
          <cylinder>
            <radius>0.3</radius>
            <length>0.2</length>
          </cylinder>
        </geometry>
      </collision>
      <visual name="visual">
        <geometry>
          <cylinder>
            <radius>0.3</radius>
            <length>0.2</length>
          </cylinder>
        </geometry>
        <material>
          <ambient>0.1 0.1 0.1 1.0</ambient>
          <diffuse>0.1 0.1 0.1 1.0</diffuse>
        </material>
      </visual>
    </link>

    <joint name="front_right_wheel_joint" type="revolute">
      <parent>base_link</parent>
      <child>front_right_wheel</child>
      <axis>
        <xyz>0 1 0</xyz>
        <limit>
            <lower>-1.79769e+308</lower>
            <upper>1.79769e+308</upper>
        </limit>
      </axis>
    </joint>

    <link name="rear_left_wheel">
      <pose relative_to="base_link">-0.7 0.75 0 -1.5708 0 0</pose>
      <inertial>
        <mass>5.0</mass>
        <inertia>
          <ixx>0.1</ixx>
          <iyy>0.1</iyy>
          <izz>0.1</izz>
        </inertia>
      </inertial>
      <collision name="collision">
        <geometry>
          <cylinder>
            <radius>0.3</radius>
            <length>0.2</length>
          </cylinder>
        </geometry>
      </collision>
      <visual name="visual">
        <geometry>
          <cylinder>
            <radius>0.3</radius>
            <length>0.2</length>
          </cylinder>
        </geometry>
        <material>
          <ambient>0.1 0.1 0.1 1.0</ambient>
          <diffuse>0.1 0.1 0.1 1.0</diffuse>
        </material>
      </visual>
    </link>

    <joint name="rear_left_wheel_joint" type="revolute">
      <parent>base_link</parent>
      <child>rear_left_wheel</child>
      <axis>
        <xyz>0 1 0</xyz>
        <limit>
            <lower>-1.79769e+308</lower>
            <upper>1.79769e+308</upper>
        </limit>
      </axis>
    </joint>

    <link name="rear_right_wheel">
      <pose relative_to="base_link">-0.7 -0.75 0 -1.5708 0 0</pose>
      <inertial>
        <mass>5.0</mass>
        <inertia>
          <ixx>0.1</ixx>
          <iyy>0.1</iyy>
          <izz>0.1</izz>
        </inertia>
      </inertial>
      <collision name="collision">
        <geometry>
          <cylinder>
            <radius>0.3</radius>
            <length>0.2</length>
          </cylinder>
        </geometry>
      </collision>
      <visual name="visual">
        <geometry>
          <cylinder>
            <radius>0.3</radius>
            <length>0.2</length>
          </cylinder>
        </geometry>
        <material>
          <ambient>0.1 0.1 0.1 1.0</ambient>
          <diffuse>0.1 0.1 0.1 1.0</diffuse>
        </material>
      </visual>
    </link>

    <joint name="rear_right_wheel_joint" type="revolute">
      <parent>base_link</parent>
      <child>rear_right_wheel</child>
      <axis>
        <xyz>0 1 0</xyz>
        <limit>
            <lower>-1.79769e+308</lower>
            <upper>1.79769e+308</upper>
        </limit>
      </axis>
    </joint>

    <!-- Differential Drive Plugin -->
    <plugin
      filename="gz-sim-diff-drive-system"
      name="gz::sim::systems::DiffDrive">
      <left_joint>front_left_wheel_joint</left_joint>
      <left_joint>rear_left_wheel_joint</left_joint>
      <right_joint>front_right_wheel_joint</right_joint>
      <right_joint>rear_right_wheel_joint</right_joint>
      <wheel_separation>1.2</wheel_separation>
      <wheel_radius>0.3</wheel_radius>
      <max_linear_acceleration>5.0</max_linear_acceleration>
      <min_linear_acceleration>-5.0</min_linear_acceleration>
      <max_angular_acceleration>5.0</max_angular_acceleration>
      <min_angular_acceleration>-5.0</min_angular_acceleration>
      <max_linear_velocity>5.0</max_linear_velocity>
      <min_linear_velocity>-5.0</min_linear_velocity>
      <max_angular_velocity>5.0</max_angular_velocity>
      <min_angular_velocity>-5.0</min_angular_velocity>
      <odom_publish_frequency>50</odom_publish_frequency>
      
      <!-- IMPORTANT: These topics are relative to /model/{name} -->
      <topic>cmd_vel</topic>
      <odom_topic>odometry</odom_topic>
      <tf_topic>tf</tf_topic>
      <frame_id>odom</frame_id>
      <child_frame_id>base_link</child_frame_id>
    </plugin>

  </model>
</sdf>
