<?xml version="1.0" ?>
<sdf version="1.8">
    <model name='smart_car'>
      <pose>0 0 0.325 0 -0 0</pose>

      <link name='chassis'>
        <pose>0 0 0.175 0 0 0</pose>
        <inertial>
          <mass>10.0</mass>
          <inertia>
            <ixx>1.0</ixx> <iyy>1.0</iyy> <izz>1.0</izz>
          </inertia>
        </inertial>
        <visual name='visual'>
          <geometry>
            <box>
              <size>2.0 1.0 0.5</size>
            </box>
          </geometry>
          <material>
            <ambient>0.0 1.0 0.0 1</ambient> <!-- Green for DiffDrive -->
            <diffuse>0.0 1.0 0.0 1</diffuse>
          </material>
        </visual>
        <collision name='collision'>
          <geometry>
            <box>
              <size>2.0 1.0 0.5</size>
            </box>
          </geometry>
        </collision>
      </link>

      <!-- Front Left Wheel -->
      <link name='front_left_wheel'>
        <pose>0.6 0.6 0.0 -1.5707 0 0</pose>
        <inertial>
          <mass>2.0</mass>
          <inertia>
            <ixx>0.1</ixx> <iyy>0.1</iyy> <izz>0.1</izz>
          </inertia>
        </inertial>
        <visual name='visual'>
          <geometry>
            <cylinder> <radius>0.3</radius> <length>0.2</length> </cylinder>
          </geometry>
          <material> <ambient>0.2 0.2 0.2 1</ambient> </material>
        </visual>
        <collision name='collision'>
          <geometry>
            <cylinder> <radius>0.3</radius> <length>0.2</length> </cylinder>
          </geometry>
          <surface>
            <friction>
              <ode> <mu>1.0</mu> <mu2>1.0</mu2> </ode>
            </friction>
          </surface>
        </collision>
      </link>

      <joint name='front_left_wheel_joint' type='revolute'>
        <parent>chassis</parent>
        <child>front_left_wheel</child>
        <axis>
          <xyz>0 0 1</xyz>
          <limit> <effort>1000</effort> <velocity>20</velocity> </limit>
        </axis>
      </joint>

      <!-- Front Right Wheel -->
      <link name='front_right_wheel'>
        <pose>0.6 -0.6 0.0 -1.5707 0 0</pose>
        <inertial>
          <mass>2.0</mass>
          <inertia>
            <ixx>0.1</ixx> <iyy>0.1</iyy> <izz>0.1</izz>
          </inertia>
        </inertial>
        <visual name='visual'>
          <geometry>
            <cylinder> <radius>0.3</radius> <length>0.2</length> </cylinder>
          </geometry>
          <material> <ambient>0.2 0.2 0.2 1</ambient> </material>
        </visual>
        <collision name='collision'>
          <geometry>
            <cylinder> <radius>0.3</radius> <length>0.2</length> </cylinder>
          </geometry>
          <surface>
            <friction>
              <ode> <mu>1.0</mu> <mu2>1.0</mu2> </ode>
            </friction>
          </surface>
        </collision>
      </link>

      <joint name='front_right_wheel_joint' type='revolute'>
        <parent>chassis</parent>
        <child>front_right_wheel</child>
        <axis>
          <xyz>0 0 1</xyz>
          <limit> <effort>1000</effort> <velocity>20</velocity> </limit>
        </axis>
      </joint>

      <!-- Rear Left Wheel -->
      <link name='rear_left_wheel'>
        <pose>-0.6 0.6 0.0 -1.5707 0 0</pose>
        <inertial>
          <mass>2.0</mass>
          <inertia>
            <ixx>0.1</ixx> <iyy>0.1</iyy> <izz>0.1</izz>
          </inertia>
        </inertial>
        <visual name='visual'>
          <geometry>
            <cylinder> <radius>0.3</radius> <length>0.2</length> </cylinder>
          </geometry>
          <material> <ambient>0.2 0.2 0.2 1</ambient> </material>
        </visual>
        <collision name='collision'>
          <geometry>
            <cylinder> <radius>0.3</radius> <length>0.2</length> </cylinder>
          </geometry>
          <surface>
            <friction>
              <ode> <mu>1.0</mu> <mu2>1.0</mu2> </ode>
            </friction>
          </surface>
        </collision>
      </link>

      <joint name='rear_left_wheel_joint' type='revolute'>
        <parent>chassis</parent>
        <child>rear_left_wheel</child>
        <axis>
          <xyz>0 0 1</xyz>
          <limit> <effort>1000</effort> <velocity>20</velocity> </limit>
        </axis>
      </joint>

      <!-- Rear Right Wheel -->
      <link name='rear_right_wheel'>
        <pose>-0.6 -0.6 0.0 -1.5707 0 0</pose>
        <inertial>
          <mass>2.0</mass>
          <inertia>
            <ixx>0.1</ixx> <iyy>0.1</iyy> <izz>0.1</izz>
          </inertia>
        </inertial>
        <visual name='visual'>
          <geometry>
            <cylinder> <radius>0.3</radius> <length>0.2</length> </cylinder>
          </geometry>
          <material> <ambient>0.2 0.2 0.2 1</ambient> </material>
        </visual>
        <collision name='collision'>
          <geometry>
            <cylinder> <radius>0.3</radius> <length>0.2</length> </cylinder>
          </geometry>
          <surface>
            <friction>
              <ode> <mu>1.0</mu> <mu2>1.0</mu2> </ode>
            </friction>
          </surface>
        </collision>
      </link>

      <joint name='rear_right_wheel_joint' type='revolute'>
        <parent>chassis</parent>
        <child>rear_right_wheel</child>
        <axis>
          <xyz>0 0 1</xyz>
          <limit> <effort>1000</effort> <velocity>20</velocity> </limit>
        </axis>
      </joint>

      <!-- Diff Drive Plugin -->
      <plugin
        filename="gz-sim-diff-drive-system"
        name="gz::sim::systems::DiffDrive">
        
        <!-- Left Wheels -->
        <left_joint>front_left_wheel_joint</left_joint>
        <left_joint>rear_left_wheel_joint</left_joint>

        <!-- Right Wheels -->
        <right_joint>front_right_wheel_joint</right_joint>
        <right_joint>rear_right_wheel_joint</right_joint>

        <wheel_separation>1.2</wheel_separation>
        <wheel_radius>0.3</wheel_radius>
        
        <max_linear_acceleration>5</max_linear_acceleration>
        <min_linear_acceleration>-5</min_linear_acceleration>
        <max_angular_acceleration>4</max_angular_acceleration>
        <min_angular_acceleration>-4</min_angular_acceleration>
        <max_linear_velocity>5.0</max_linear_velocity>
        <min_linear_velocity>-5.0</min_linear_velocity>
        <max_angular_velocity>4.0</max_angular_velocity>
        <min_angular_velocity>-4.0</min_angular_velocity>
        
        <topic>cmd_vel</topic>
        <odom_topic>odometry</odom_topic>
        <frame_id>odom</frame_id>
        <child_frame_id>chassis</child_frame_id>
      </plugin>

    </model>
</sdf>
